Workbook

Sheet Boxes
A1: Refinery boxes — net naphtha = capacity x utilization x signed yields. Blue = input, orange = manual override (clear to fall back to the Assumptions sheet), grey = formula. Yield-mode rows read the Data sheet.
A2: row | B2: refinery_id | C2: padd | D2: unit | E2: type | F2: cap kbd | G2: util ovr | H2: util | I2: LVN ovr | J2: LVN yield | K2: HVN ovr | L2: HVN yield | M2: Σ yield | N2: net naphtha kbd
A3: Phillips 66 Co. Linden [PHILLIPS_LINDEN] — Phillips 66 Co. — PADD 1 — crude 258 kbd
A4: UNIT | B4: PHILLIPS_LINDEN | C4: 1 | D4: CRUDE-EST | E4: est. yield | F4: =SUMIFS(Data!$G$3:$G$125,Data!$A$3:$A$125,$B4) | H4: =IF($G4<>"",$G4,SUMIFS(Assumptions!$K$4:$K$8,Assumptions!$J$4:$J$8,$C4)) | J4: =IF($I4<>"",$I4,SUMIFS(Data!$N$3:$N$125,Data!$A$3:$A$125,$B4)*Assumptions!$S$4) | L4: =IF($K4<>"",$K4,SUMIFS(Data!$N$3:$N$125,Data!$A$3:$A$125,$B4)*Assumptions!$S$5) | M4: =J4+L4 | N4: =$F4*$H4*$M4
A5: TOTAL | B5: PHILLIPS_LINDEN | C5: 1 | D5: NET NAPHTHA | N5: =SUM(N4:N4)
A7: Monroe Energy Trainer [MONROE_TRAINER] — Delta Airlines — PADD 1 — crude 185 kbd
A8: UNIT | B8: MONROE_TRAINER | C8: 1 | D8: CRUDE-EST | E8: est. yield | F8: =SUMIFS(Data!$G$3:$G$125,Data!$A$3:$A$125,$B8) | H8: =IF($G8<>"",$G8,SUMIFS(Assumptions!$K$4:$K$8,Assumptions!$J$4:$J$8,$C8)) | J8: =IF($I8<>"",$I8,SUMIFS(Data!$N$3:$N$125,Data!$A$3:$A$125,$B8)*Assumptions!$S$4) | L8: =IF($K8<>"",$K8,SUMIFS(Data!$N$3:$N$125,Data!$A$3:$A$125,$B8)*Assumptions!$S$5) | M8: =J8+L8 | N8: =$F8*$H8*$M8
A9: TOTAL | B9: MONROE_TRAINER | C9: 1 | D9: NET NAPHTHA | N9: =SUM(N8:N8)
A11: PBF Energy Company LLC Delaware City [PBF_DELAWARE_CITY] — PBF Energy Company LLC — PADD 1 — crude 180 kbd
A12: UNIT | B12: PBF_DELAWARE_CITY | C12: 1 | D12: CRUDE-EST | E12: est. yield | F12: =SUMIFS(Data!$G$3:$G$125,Data!$A$3:$A$125,$B12) | H12: =IF($G12<>"",$G12,SUMIFS(Assumptions!$K$4:$K$8,Assumptions!$J$4:$J$8,$C12)) | J12: =IF($I12<>"",$I12,SUMIFS(Data!$N$3:$N$125,Data!$A$3:$A$125,$B12)*Assumptions!$S$4) | L12: =IF($K12<>"",$K12,SUMIFS(Data!$N$3:$N$125,Data!$A$3:$A$125,$B12)*Assumptions!$S$5) | M12: =J12+L12 | N12: =$F12*$H12*$M12
A13: TOTAL | B13: PBF_DELAWARE_CITY | C13: 1 | D13: NET NAPHTHA | N13: =SUM(N12:N12)
A15: PBF Energy Company LLC Paulsboro [PBF_PAULSBORO] — PBF Energy Company LLC — PADD 1 — crude 100 kbd
A16: UNIT | B16: PBF_PAULSBORO | C16: 1 | D16: CRUDE-EST | E16: est. yield | F16: =SUMIFS(Data!$G$3:$G$125,Data!$A$3:$A$125,$B16) | H16: =IF($G16<>"",$G16,SUMIFS(Assumptions!$K$4:$K$8,Assumptions!$J$4:$J$8,$C16)) | J16: =IF($I16<>"",$I16,SUMIFS(Data!$N$3:$N$125,Data!$A$3:$A$125,$B16)*Assumptions!$S$4) | L16: =IF($K16<>"",$K16,SUMIFS(Data!$N$3:$N$125,Data!$A$3:$A$125,$B16)*Assumptions!$S$5) | M16: =J16+L16 | N16: =$F16*$H16*$M16
A17: TOTAL | B17: PBF_PAULSBORO | C17: 1 | D17: NET NAPHTHA | N17: =SUM(N16:N16)
A19: United Refining Warren [UNITED_WARREN] — United Refining — PADD 1 — crude 70 kbd
A20: UNIT | B20: UNITED_WARREN | C20: 1 | D20: CRUDE-EST | E20: est. yield | F20: =SUMIFS(Data!$G$3:$G$125,Data!$A$3:$A$125,$B20) | H20: =IF($G20<>"",$G20,SUMIFS(Assumptions!$K$4:$K$8,Assumptions!$J$4:$J$8,$C20)) | J20: =IF($I20<>"",$I20,SUMIFS(Data!$N$3:$N$125,Data!$A$3:$A$125,$B20)*Assumptions!$S$4) | L20: =IF($K20<>"",$K20,SUMIFS(Data!$N$3:$N$125,Data!$A$3:$A$125,$B20)*Assumptions!$S$5) | M20: =J20+L20 | N20: =$F20*$H20*$M20
A21: TOTAL | B21: UNITED_WARREN | C21: 1 | D21: NET NAPHTHA | N21: =SUM(N20:N20)
A23: Ergon Newell [ERGON_NEWELL] — Ergon — PADD 1 — crude 22 kbd
A24: UNIT | B24: ERGON_NEWELL | C24: 1 | D24: CRUDE-EST | E24: est. yield | F24: =SUMIFS(Data!$G$3:$G$125,Data!$A$3:$A$125,$B24) | H24: =IF($G24<>"",$G24,SUMIFS(Assumptions!$K$4:$K$8,Assumptions!$J$4:$J$8,$C24)) | J24: =IF($I24<>"",$I24,SUMIFS(Data!$N$3:$N$125,Data!$A$3:$A$125,$B24)*Assumptions!$S$4) | L24: =IF($K24<>"",$K24,SUMIFS(Data!$N$3:$N$125,Data!$A$3:$A$125,$B24)*Assumptions!$S$5) | M24: =J24+L24 | N24: =$F24*$H24*$M24
A25: TOTAL | B25: ERGON_NEWELL | C25: 1 | D25: NET NAPHTHA | N25: =SUM(N24:N24)
A27: American Refining Group Bradford [AMERICAN_BRADFORD] — American Refining Group — PADD 1 — crude 12 kbd
A28: UNIT | B28: AMERICAN_BRADFORD | C28: 1 | D28: CRUDE-EST | E28: est. yield | F28: =SUMIFS(Data!$G$3:$G$125,Data!$A$3:$A$125,$B28) | H28: =IF($G28<>"",$G28,SUMIFS(Assumptions!$K$4:$K$8,Assumptions!$J$4:$J$8,$C28)) | J28: =IF($I28<>"",$I28,SUMIFS(Data!$N$3:$N$125,Data!$A$3:$A$125,$B28)*Assumptions!$S$4) | L28: =IF($K28<>"",$K28,SUMIFS(Data!$N$3:$N$125,Data!$A$3:$A$125,$B28)*Assumptions!$S$5) | M28: =J28+L28 | N28: =$F28*$H28*$M28
A29: TOTAL | B29: AMERICAN_BRADFORD | C29: 1 | D29: NET NAPHTHA | N29: =SUM(N28:N28)
A31: BP Whiting [BP_WHITING] — BP — PADD 2 — crude 435 kbd
A32: UNIT | B32: BP_WHITING | C32: 2 | D32: CRUDE-EST | E32: est. yield | F32: =SUMIFS(Data!$G$3:$G$125,Data!$A$3:$A$125,$B32) | H32: =IF($G32<>"",$G32,SUMIFS(Assumptions!$K$4:$K$8,Assumptions!$J$4:$J$8,$C32)) | J32: =IF($I32<>"",$I32,SUMIFS(Data!$N$3:$N$125,Data!$A$3:$A$125,$B32)*Assumptions!$S$4) | L32: =IF($K32<>"",$K32,SUMIFS(Data!$N$3:$N$125,Data!$A$3:$A$125,$B32)*Assumptions!$S$5) | M32: =J32+L32 | N32: =$F32*$H32*$M32
A33: TOTAL | B33: BP_WHITING | C33: 2 | D33: NET NAPHTHA | N33: =SUM(N32:N32)
A35: Flint Hills Resources Rosemount [FLINT_ROSEMOUNT] — Koch Industries — PADD 2 — crude 375 kbd
A36: UNIT | B36: FLINT_ROSEMOUNT | C36: 2 | D36: CRUDE-EST | E36: est. yield | F36: =SUMIFS(Data!$G$3:$G$125,Data!$A$3:$A$125,$B36) | H36: =IF($G36<>"",$G36,SUMIFS(Assumptions!$K$4:$K$8,Assumptions!$J$4:$J$8,$C36)) | J36: =IF($I36<>"",$I36,SUMIFS(Data!$N$3:$N$125,Data!$A$3:$A$125,$B36)*Assumptions!$S$4) | L36: =IF($K36<>"",$K36,SUMIFS(Data!$N$3:$N$125,Data!$A$3:$A$125,$B36)*Assumptions!$S$5) | M36: =J36+L36 | N36: =$F36*$H36*$M36
A37: TOTAL | B37: FLINT_ROSEMOUNT | C37: 2 | D37: NET NAPHTHA | N37: =SUM(N36:N36)
A39: Cenovus Wood River [CENOVUS_WOOD_RIVER] — Cenovus (50%) / Phillips 66 Co. (50%) — PADD 2 — crude 356 kbd
A40: UNIT | B40: CENOVUS_WOOD_RIVER | C40: 2 | D40: CRUDE-EST | E40: est. yield | F40: =SUMIFS(Data!$G$3:$G$125,Data!$A$3:$A$125,$B40) | H40: =IF($G40<>"",$G40,SUMIFS(Assumptions!$K$4:$K$8,Assumptions!$J$4:$J$8,$C40)) | J40: =IF($I40<>"",$I40,SUMIFS(Data!$N$3:$N$125,Data!$A$3:$A$125,$B40)*Assumptions!$S$4) | L40: =IF($K40<>"",$K40,SUMIFS(Data!$N$3:$N$125,Data!$A$3:$A$125,$B40)*Assumptions!$S$5) | M40: =J40+L40 | N40: =$F40*$H40*$M40
A41: TOTAL | B41: CENOVUS_WOOD_RIVER | C41: 2 | D41: NET NAPHTHA | N41: =SUM(N40:N40)
A43: Marathon Petroleum Catlettsburg [MARATHON_CATLETTSBURG] — Marathon Petroleum — PADD 2 — crude 316 kbd
A44: UNIT | B44: MARATHON_CATLETTSBURG | C44: 2 | D44: CRUDE-EST | E44: est. yield | F44: =SUMIFS(Data!$G$3:$G$125,Data!$A$3:$A$125,$B44) | H44: =IF($G44<>"",$G44,SUMIFS(Assumptions!$K$4:$K$8,Assumptions!$J$4:$J$8,$C44)) | J44: =IF($I44<>"",$I44,SUMIFS(Data!$N$3:$N$125,Data!$A$3:$A$125,$B44)*Assumptions!$S$4) | L44: =IF($K44<>"",$K44,SUMIFS(Data!$N$3:$N$125,Data!$A$3:$A$125,$B44)*Assumptions!$S$5) | M44: =J44+L44 | N44: =$F44*$H44*$M44
A45: TOTAL | B45: MARATHON_CATLETTSBURG | C45: 2 | D45: NET NAPHTHA | N45: =SUM(N44:N44)
A47: Marathon Petroleum Robinson [MARATHON_ROBINSON] — Marathon Petroleum — PADD 2 — crude 278 kbd
A48: UNIT | B48: MARATHON_ROBINSON | C48: 2 | D48: CRUDE-EST | E48: est. yield | F48: =SUMIFS(Data!$G$3:$G$125,Data!$A$3:$A$125,$B48) | H48: =IF($G48<>"",$G48,SUMIFS(Assumptions!$K$4:$K$8,Assumptions!$J$4:$J$8,$C48)) | J48: =IF($I48<>"",$I48,SUMIFS(Data!$N$3:$N$125,Data!$A$3:$A$125,$B48)*Assumptions!$S$4) | L48: =IF($K48<>"",$K48,SUMIFS(Data!$N$3:$N$125,Data!$A$3:$A$125,$B48)*Assumptions!$S$5) | M48: =J48+L48 | N48: =$F48*$H48*$M48
A49: TOTAL | B49: MARATHON_ROBINSON | C49: 2 | D49: NET NAPHTHA | N49: =SUM(N48:N48)
A51: ExxonMobil Joliet [EXXONMOBIL_JOLIET] — ExxonMobil — PADD 2 — crude 252 kbd
A52: UNIT | B52: EXXONMOBIL_JOLIET | C52: 2 | D52: CRUDE-EST | E52: est. yield | F52: =SUMIFS(Data!$G$3:$G$125,Data!$A$3:$A$125,$B52) | H52: =IF($G52<>"",$G52,SUMIFS(Assumptions!$K$4:$K$8,Assumptions!$J$4:$J$8,$C52)) | J52: =IF($I52<>"",$I52,SUMIFS(Data!$N$3:$N$125,Data!$A$3:$A$125,$B52)*Assumptions!$S$4) | L52: =IF($K52<>"",$K52,SUMIFS(Data!$N$3:$N$125,Data!$A$3:$A$125,$B52)*Assumptions!$S$5) | M52: =J52+L52 | N52: =$F52*$H52*$M52
...

Sheet Assumptions
A1: Assumptions — blue cells are inputs. Yields are % of unit throughput; consumers (reformer/isom) are NEGATIVE. Edits flow straight into the Boxes sheet.
A3: PADD 1 — East Coast | J3: padd | K3: util | M3: padd | N3: unit_type | O3: cut | P3: yield | R3: Yield-mode cut split | S3: share
A4: Utilization | B4: 0.9 | J4: 1 | K4: =B4 | M4: 1 | N4: CDU | O4: LVN | P4: =B7 | R4: LVN | S4: 0.35
J5: 2 | K5: =B19 | M5: 1 | N5: CDU | O5: HVN | P5: =C7 | R5: HVN | S5: 0.65
A6: Unit type | B6: LVN | C6: HVN | J6: 3 | K6: =B34 | M6: 1 | N6: VDU | O6: LVN | P6: =B8
A7: CDU | B7: 0.05 | C7: 0.13 | J7: 4 | K7: =B49 | M7: 1 | N7: VDU | O7: HVN | P7: =C8 | R7: how a yield-mode refinery's 2024 net yield splits across cuts
A8: VDU | B8: 0 | C8: 0.01 | J8: 5 | K8: =B64 | M8: 1 | N8: FCC | O8: LVN | P8: =B9
A9: FCC | B9: 0.02 | C9: 0.04 | M9: 1 | N9: FCC | O9: HVN | P9: =C9
A10: COKER | B10: 0.02 | C10: 0.08 | M10: 1 | N10: COKER | O10: LVN | P10: =B10
A11: HYDROCRACKER | B11: 0.05 | C11: 0.15 | M11: 1 | N11: COKER | O11: HVN | P11: =C10
A12: REFORMER | B12: 0 | C12: -1 | M12: 1 | N12: HYDROCRACKER | O12: LVN | P12: =B11
A13: ISOM | B13: -1 | C13: 0 | M13: 1 | N13: HYDROCRACKER | O13: HVN | P13: =C11
A14: ALKY | B14: 0 | C14: 0 | M14: 1 | N14: REFORMER | O14: LVN | P14: =B12
A15: SPLITTER | B15: 0.25 | C15: 0.35 | M15: 1 | N15: REFORMER | O15: HVN | P15: =C12
M16: 1 | N16: ISOM | O16: LVN | P16: =B13
M17: 1 | N17: ISOM | O17: HVN | P17: =C13
A18: PADD 2 — Midwest | M18: 1 | N18: ALKY | O18: LVN | P18: =B14
A19: Utilization | B19: 0.9 | M19: 1 | N19: ALKY | O19: HVN | P19: =C14
M20: 1 | N20: SPLITTER | O20: LVN | P20: =B15
A21: Unit type | B21: LVN | C21: HVN | M21: 1 | N21: SPLITTER | O21: HVN | P21: =C15
A22: CDU | B22: 0.05 | C22: 0.13 | M22: 2 | N22: CDU | O22: LVN | P22: =B22
A23: VDU | B23: 0 | C23: 0.01 | M23: 2 | N23: CDU | O23: HVN | P23: =C22
A24: FCC | B24: 0.02 | C24: 0.04 | M24: 2 | N24: VDU | O24: LVN | P24: =B23
A25: COKER | B25: 0.02 | C25: 0.08 | M25: 2 | N25: VDU | O25: HVN | P25: =C23
A26: HYDROCRACKER | B26: 0.05 | C26: 0.15 | M26: 2 | N26: FCC | O26: LVN | P26: =B24
A27: REFORMER | B27: 0 | C27: -1 | M27: 2 | N27: FCC | O27: HVN | P27: =C24
A28: ISOM | B28: -1 | C28: 0 | M28: 2 | N28: COKER | O28: LVN | P28: =B25
A29: ALKY | B29: 0 | C29: 0 | M29: 2 | N29: COKER | O29: HVN | P29: =C25
A30: SPLITTER | B30: 0.25 | C30: 0.35 | M30: 2 | N30: HYDROCRACKER | O30: LVN | P30: =B26
M31: 2 | N31: HYDROCRACKER | O31: HVN | P31: =C26
M32: 2 | N32: REFORMER | O32: LVN | P32: =B27
A33: PADD 3 — Gulf Coast | M33: 2 | N33: REFORMER | O33: HVN | P33: =C27
A34: Utilization | B34: 0.93 | M34: 2 | N34: ISOM | O34: LVN | P34: =B28
M35: 2 | N35: ISOM | O35: HVN | P35: =C28
A36: Unit type | B36: LVN | C36: HVN | M36: 2 | N36: ALKY | O36: LVN | P36: =B29
A37: CDU | B37: 0.055 | C37: 0.135 | M37: 2 | N37: ALKY | O37: HVN | P37: =C29
A38: VDU | B38: 0 | C38: 0.01 | M38: 2 | N38: SPLITTER | O38: LVN | P38: =B30
A39: FCC | B39: 0.02 | C39: 0.04 | M39: 2 | N39: SPLITTER | O39: HVN | P39: =C30
A40: COKER | B40: 0.02 | C40: 0.08 | M40: 3 | N40: CDU | O40: LVN | P40: =B37
A41: HYDROCRACKER | B41: 0.05 | C41: 0.15 | M41: 3 | N41: CDU | O41: HVN | P41: =C37
...

Sheet Data
A1: Imported data — refinery registry + 2024 net yields (% of crude). Type a crude capacity (blue) and that refinery's box lights up. Re-import: python -m naphtha_model ingest-yields <file>
A2: refinery_id | B2: name | C2: owner | D2: padd | E2: state | F2: city | G2: crude_capacity_kbd | H2: status | I2: gasoil_diesel | J2: gasoline | K2: hfo | L2: kero_jet | M2: lpg | N2: naphtha | O2: total
A3: PHILLIPS_LINDEN | B3: Phillips 66 Co. Linden | C3: Phillips 66 Co. | D3: 1 | E3: New Jersey | F3: Linden | G3: 258 | H3: operating | I3: 0.320086 | J3: 0.513787 | K3: 0.001038 | L3: 0.097992 | M3: 0.024308 | N3: 0 | O3: 0.95721
A4: MONROE_TRAINER | B4: Monroe Energy Trainer | C4: Delta Airlines | D4: 1 | E4: Pennsylvania | F4: Trainer | G4: 185 | H4: operating | I4: 0.19063 | J4: 0.572953 | K4: 0.012446 | L4: 0.196579 | M4: 0.014049 | N4: 0 | O4: 0.986657
A5: PBF_DELAWARE_CITY | B5: PBF Energy Company LLC Delaware City | C5: PBF Energy Company LLC | D5: 1 | E5: Delaware | F5: Delaware City | G5: 180 | H5: operating | I5: 0.288664 | J5: 0.626601 | K5: 0.006596 | L5: 0.118778 | M5: 0.027567 | N5: 0 | O5: 1.068205
A6: PBF_PAULSBORO | B6: PBF Energy Company LLC Paulsboro | C6: PBF Energy Company LLC | D6: 1 | E6: New Jersey | F6: Paulsboro | G6: 100 | H6: operating | I6: 0.373933 | J6: 0.272644 | K6: 0.024194 | L6: 0.199112 | M6: 0.009816 | N6: 0 | O6: 0.879698
A7: UNITED_WARREN | B7: United Refining Warren | C7: United Refining | D7: 1 | E7: Pennsylvania | F7: Warren | G7: 70 | H7: operating | I7: 0.174032 | J7: 0.450898 | K7: 0.001753 | L7: 0 | M7: 0.000756 | N7: 0 | O7: 0.627437
A8: ERGON_NEWELL | B8: Ergon Newell | C8: Ergon | D8: 1 | E8: West Virginia | F8: Newell | G8: 22.3 | H8: operating | I8: 0.276305 | J8: 0.340546 | K8: 0 | L8: 0 | M8: 0.001903 | N8: 0 | O8: 0.618754
A9: AMERICAN_BRADFORD | B9: American Refining Group Bradford | C9: American Refining Group | D9: 1 | E9: Pennsylvania | F9: Bradford | G9: 11.8 | H9: operating | I9: 0.240976 | J9: 0.368069 | K9: 0 | L9: 0 | M9: 0.00557 | N9: 0 | O9: 0.614615
A10: BP_WHITING | B10: BP Whiting | C10: BP | D10: 2 | E10: Indiana | F10: Whiting | G10: 435 | H10: operating | I10: 0.232409 | J10: 0.573591 | K10: 0.010617 | L10: 0.069983 | M10: 0.018035 | N10: 0.00217 | O10: 0.906804
A11: FLINT_ROSEMOUNT | B11: Flint Hills Resources Rosemount | C11: Koch Industries | D11: 2 | E11: Minnesota | F11: Rosemount | G11: 375 | H11: operating | I11: 0.115114 | J11: 0.666609 | K11: 0.022427 | L11: 0.112758 | M11: 0.014163 | N11: 0.010141 | O11: 0.941212
A12: CENOVUS_WOOD_RIVER | B12: Cenovus Wood River | C12: Cenovus (50%) / Phillips 66 Co. (50%) | D12: 2 | E12: Illinois | F12: Wood River | G12: 356 | H12: operating | I12: 0.064308 | J12: 0.361823 | K12: 0.010296 | L12: 0.034763 | M12: 0.003792 | N12: 0.001431 | O12: 0.476413
A13: MARATHON_CATLETTSBURG | B13: Marathon Petroleum Catlettsburg | C13: Marathon Petroleum | D13: 2 | E13: Kentucky | F13: Catlettsburg | G13: 316 | H13: operating | I13: 0.478289 | J13: 0.434757 | K13: 0.001486 | L13: 0.020455 | M13: 0.009076 | N13: 0.001714 | O13: 0.945778
A14: MARATHON_ROBINSON | B14: Marathon Petroleum Robinson | C14: Marathon Petroleum | D14: 2 | E14: Illinois | F14: Robinson | G14: 278 | H14: operating | I14: 0.395003 | J14: 0.537607 | K14: 0.010142 | L14: 0.021377 | M14: 0.005884 | N14: 0.00261 | O14: 0.972624
... A125: VALERO_BENICIA | B125: Valero Benicia | C125: Valero | D125: 5 | E125: California | F125: Benicia | G125: 0 | H125: shut | I125: 0.227784 | J125: 0.676343 | K125: 0.012873 | L125: 0.101721 | M125: 0.004105 | N125: 0.000439 | O125: 1.023265
